<?xml version="1.0"?>
<robot xmlns:xacro="http://www.ros.org/wiki/xacro" name="peijian">

<!--macro for peijian description -->
  <xacro:macro name="peijian">



  <!-- link  yg1220_1_1   -->
  <link
    name="yg1220_1_1">
    <inertial>
      <origin
        xyz="6.3838E-15 6.6613E-15 0.76602"
        rpy="0 0 0" />
      <mass
        value="12.766" />
      <inertia
        ixx="3.6006"
        ixy="-2.0103E-17"
        ixz="8.5001E-16"
        iyy="3.6026"
        iyz="1.1691E-16"
        izz="0.051461" />
    </inertial>
    <visual>
      <origin
        xyz="0 0 0"
        rpy="0 0 0" />
      <geometry>
        <mesh
          filename="package://pudong/meshes/yg1220_1_1.STL" />
      </geometry>
      <material
        name="">
        <color
          rgba="1 0 0 1" />
      </material>
    </visual>
    <collision>
      <origin
        xyz="0 0 0"
        rpy="0 0 0" />
      <geometry>
        <mesh
          filename="package://pudong/meshes/yg1220_1_1.STL" />
      </geometry>
    </collision>
  </link>

  <!--  joint: cheshen_to_1220_1  -->
  <joint
    name="cheshen_to_1220_1"
    type="revolute">
    <origin
      xyz="0.461 0.31 0.44"
      rpy="0 0.46835 0" />  <!-- 0.55538  -->
    <parent
      link="cheshen" />
    <child
      link="yg1220_1_1" />
    <axis
      xyz="0 1 0" />
    <limit
      lower="-1.0"
      upper="0.5"
      effort="0"
      velocity="1" />
  </joint>

  <!--    yg1220_1_2  -->
  <link
    name="yg1220_1_2">
    <inertial>
      <origin
        xyz="5.8287E-15 3.1086E-15 0.75378"
        rpy="0 0 0" />
      <mass
        value="8.7504" />
      <inertia
        ixx="2.1109"
        ixy="6.2989E-19"
        ixz="4.0658E-16"
        iyy="2.1113"
        iyz="6.698E-15"
        izz="0.0084603" />
    </inertial>
    <visual>
      <origin
        xyz="0 0 0"
        rpy="0 0 0" />
      <geometry>
        <mesh
          filename="package://pudong/meshes/yg1220_1_2.STL" />
      </geometry>
      <material
        name="">
        <color
          rgba="1 0 0 1" />
      </material>
    </visual>
    <collision>
      <origin
        xyz="0 0 0"
        rpy="0 0 0" />
      <geometry>
        <mesh
          filename="package://pudong/meshes/yg1220_1_2.STL" />
      </geometry>
    </collision>
  </link>

  <!--  joint: yg1220_1  -->
  <joint
    name="yg1220_1"
    type="prismatic">
    <origin
      xyz="0 0 1.0248156"  
      rpy="0 0 0" />  <!--  0.95471   -->
    <parent
      link="yg1220_1_1" />
    <child
      link="yg1220_1_2" />
    <axis
      xyz="0 0 -1" />
    <limit
      lower="-0.42"
      upper="0.8"
      effort="0"
      velocity="1" />
  </joint>

  <!--    yg1220_2_1  -->
  <link
    name="yg1220_2_1">
    <inertial>
      <origin
        xyz="4.885E-15 4.6629E-15 0.76602"
        rpy="0 0 0" />
      <mass
        value="12.766" />
      <inertia
        ixx="3.6006"
        ixy="-2.0289E-17"
        ixz="7.1818E-16"
        iyy="3.6026"
        iyz="2.2196E-15"
        izz="0.051461" />
    </inertial>
    <visual>
      <origin
        xyz="0 0 0"
        rpy="0 0 0" />
      <geometry>
        <mesh
          filename="package://pudong/meshes/yg1220_2_1.STL" />
      </geometry>
      <material
        name="">
        <color
          rgba="1 0 0 1" />
      </material>
    </visual>
    <collision>
      <origin
        xyz="0 0 0"
        rpy="0 0 0" />
      <geometry>
        <mesh
          filename="package://pudong/meshes/yg1220_2_1.STL" />
      </geometry>
    </collision>
  </link>

  <!-- joint: cheshen_to_1220_2  -->
  <joint
    name="cheshen_to_1220_2"
    type="revolute">
    <origin
      xyz="0.461 -0.31 0.44"
      rpy="0 0.46835 0" />
    <parent
      link="cheshen" />
    <child
      link="yg1220_2_1" />
    <axis
      xyz="0 1 0" />
    <limit
      lower="-1.0"
      upper="0.5"
      effort="0"
      velocity="1" />
    <mimic
      joint="cheshen_to_1220_1"
      multiplier="1"
      offset="0" />
  </joint>

  <!--  yg1220_2_2    -->
  <link
    name="yg1220_2_2">
    <inertial>
      <origin
        xyz="4.2744E-15 3.3307E-15 0.75378"
        rpy="0 0 0" />
      <mass
        value="8.7504" />
      <inertia
        ixx="2.1109"
        ixy="-5.507E-18"
        ixz="-1.5266E-16"
        iyy="2.1113"
        iyz="6.6736E-15"
        izz="0.0084603" />
    </inertial>
    <visual>
      <origin
        xyz="0 0 0"
        rpy="0 0 0" />
      <geometry>
        <mesh
          filename="package://pudong/meshes/yg1220_2_2.STL" />
      </geometry>
      <material
        name="">
        <color
          rgba="1 0 0 1" />
      </material>
    </visual>
    <collision>
      <origin
        xyz="0 0 0"
        rpy="0 0 0" />
      <geometry>
        <mesh
          filename="package://pudong/meshes/yg1220_2_2.STL" />
      </geometry>
    </collision>
  </link>

  <!--  joint: yg1220_2   -->
  <joint
    name="yg1220_2"
    type="prismatic">
    <origin
      xyz="0 0 1.0248156"
      rpy="0 0 0" />
    <parent
      link="yg1220_2_1" />
    <child
      link="yg1220_2_2" />
    <axis
      xyz="0 0 -1" />
    <limit
      lower="-0.42"
      upper="0.8"
      effort="0"
      velocity="1" />
    <mimic
      joint="yg1220_1"
      multiplier="1"
      offset="0" />
  </joint>

  <!--    yg1480     -->
  <link
    name="yg1480">
    <inertial>
      <origin
        xyz="2.2204E-15 1.0436E-14 0.88447"
        rpy="0 0 0" />
      <mass
        value="15.576" />
      <inertia
        ixx="5.7795"
        ixy="3.8423E-17"
        ixz="3.773E-16"
        iyy="5.782"
        iyz="-3.0915E-17"
        izz="0.073091" />
    </inertial>
    <visual>
      <origin
        xyz="0 0 0"
        rpy="0 0 0" />
      <geometry>
        <mesh
          filename="package://pudong/meshes/yg1480.STL" />
      </geometry>
      <material
        name="">
        <color
          rgba="0 1 1 1" />
      </material>
    </visual>
    <collision>
      <origin
        xyz="0 0 0"
        rpy="0 0 0" />
      <geometry>
        <mesh
          filename="package://pudong/meshes/yg1480.STL" />
      </geometry>
    </collision>
  </link>

  <!-- joint: t03_to_1480   -->
  <joint
    name="t03_to_1480"
    type="revolute">
    <origin
      xyz="2.7108 0 2.1303"
      rpy="0 1.4036 0" />
    <parent
      link="pjjq03" />
    <child
      link="yg1480" />
    <axis
      xyz="0 -1 0" />
    <limit
      lower="-0.2"
      upper="0.2"
      effort="0"
      velocity="1" />
  </joint>

  <!--  yg1480_2    -->
  <link
    name="yg1480_2">
    <inertial>
      <origin
        xyz="3.9968E-15 9.1038E-15 0.91721"
        rpy="0 0 0" />
      <mass
        value="15.423" />
      <inertia
        ixx="4.9237"
        ixy="4.5322E-18"
        ixz="4.8182E-16"
        iyy="4.9253"
        iyz="-1.1532E-16"
        izz="0.021379" />
    </inertial>
    <visual>
      <origin
        xyz="0 0 0"
        rpy="0 0 0" />
      <geometry>
        <mesh
          filename="package://pudong/meshes/yg1480_2.STL" />
      </geometry>
      <material
        name="">
        <color
          rgba="0.086275 0.21961 1 1" />
      </material>
    </visual>
    <collision>
      <origin
        xyz="0 0 0"
        rpy="0 0 0" />
      <geometry>
        <mesh
          filename="package://pudong/meshes/yg1480_2.STL" />
      </geometry>
    </collision>
  </link>

  <!-- joint: t1480_1_to_2   -->
  <joint
    name="t1480_1_to_2"
    type="prismatic">
    <origin
      xyz="0 0 0.7811"
      rpy="0 0 0" />
    <parent
      link="yg1480" />
    <child
      link="yg1480_2" />
    <axis
      xyz="0 0 -1" />
    <limit
      lower="-0.88"
      upper="0.6"
      effort="0"
      velocity="1" />
  </joint>

  <!--  yg1050    -->>
  <link
    name="yg1050">
    <inertial>
      <origin
        xyz="8.9706E-14 7.7716E-15 0.68295"
        rpy="0 0 0" />
      <mass
        value="11.684" />
      <inertia
        ixx="2.6743"
        ixy="3.8052E-18"
        ixz="-4.0853E-16"
        iyy="2.6763"
        iyz="-1.2435E-16"
        izz="0.046473" />
    </inertial>
    <visual>
      <origin
        xyz="0 0 0"
        rpy="0 0 0" />
      <geometry>
        <mesh
          filename="package://pudong/meshes/yg1050.STL" />
      </geometry>
      <material
        name="">
        <color
          rgba="1 0 1 1" />
      </material>
    </visual>
    <collision>
      <origin
        xyz="0 0 0"
        rpy="0 0 0" />
      <geometry>
        <mesh
          filename="package://pudong/meshes/yg1050.STL" />
      </geometry>
    </collision>
  </link>

  <!-- joint:  t04_to_1050  -->
  <joint
    name="t04_to_1050"
    type="revolute">
    <origin
      xyz="0.40628 0 0.76931"
      rpy="-3.1416 1.4945 -3.1416" />
    <parent
      link="pjjq04" />
    <child
      link="yg1050" />
    <axis
      xyz="0 -1 0" />
    <limit
      lower="-0.1"
      upper="0.3"
      effort="0"
      velocity="1" />
  </joint>

  <!-- yg1050_2   -->
  <link
    name="yg1050_2">
    <inertial>
      <origin
        xyz="8.9706E-14 4.6629E-15 0.69365"
        rpy="0 0 0" />
      <mass
        value="8.1381" />
      <inertia
        ixx="1.6884"
        ixy="-2.173E-18"
        ixz="1.1427E-16"
        iyy="1.6889"
        iyz="-1.8072E-15"
        izz="0.0079769" />
    </inertial>
    <visual>
      <origin
        xyz="0 0 0"
        rpy="0 0 0" />
      <geometry>
        <mesh
          filename="package://pudong/meshes/yg1050_2.STL" />
      </geometry>
      <material
        name="">
        <color
          rgba="0 1 1 1" />
      </material>
    </visual>
    <collision>
      <origin
        xyz="0 0 0"
        rpy="0 0 0" />
      <geometry>
        <mesh
          filename="package://pudong/meshes/yg1050_2.STL" />
      </geometry>
    </collision>
  </link>

  <!--  joint: t1050_1_to_2   -->
  <joint
    name="t1050_1_to_2"
    type="prismatic">
    <origin
      xyz="0 0 1.0701"
      rpy="0 0 0" />
    <parent
      link="yg1050" />
    <child
      link="yg1050_2" />
    <axis
      xyz="0 0 -1" />
    <limit
      lower="-0.1"
      upper="0.95"
      effort="0"
      velocity="1" />
  </joint>

  <!--  pjjq05_1    -->
  <link
    name="pjjq05_1">
    <inertial>
      <origin
        xyz="-4.4409E-15 3.5527E-15 0.305"
        rpy="0 0 0" />
      <mass
        value="3.6933" />
      <inertia
        ixx="0.17974"
        ixy="-1.2585E-18"
        ixz="1.8865E-17"
        iyy="0.18482"
        iyz="-2.112E-17"
        izz="0.0060665" />
    </inertial>
    <visual>
      <origin
        xyz="0 0 0"
        rpy="0 0 0" />
      <geometry>
        <mesh
          filename="package://pudong/meshes/pjjq05_1.STL" />
      </geometry>
      <material
        name="">
        <color
          rgba="1 0.49804 0 1" />
      </material>
    </visual>
    <collision>
      <origin
        xyz="0 0 0"
        rpy="0 0 0" />
      <geometry>
        <mesh
          filename="package://pudong/meshes/pjjq05_1.STL" />
      </geometry>
    </collision>
  </link>

  <!--  joint:  t04_to_05_1  -->
  <joint
    name="t04_to_05_1"
    type="revolute">
    <origin
      xyz="2.4617 -0.17 0.17367"
      rpy="0 0.84777 0" />
    <parent
      link="pjjq04" />
    <child
      link="pjjq05_1" />
    <axis
      xyz="0 1 0" />
    <limit
      lower="-1.7"
      upper="0.5"
      effort="0"
      velocity="1" />
  </joint>

  <!--  pjjq05_2   -->
  <link
    name="pjjq05_2">
    <inertial>
      <origin
        xyz="-4.885E-15 4.4409E-15 0.305"
        rpy="0 0 0" />
      <mass
        value="3.6933" />
      <inertia
        ixx="0.17974"
        ixy="1.9711E-18"
        ixz="5.5077E-17"
        iyy="0.18482"
        iyz="1.2286E-17"
        izz="0.0060665" />
    </inertial>
    <visual>
      <origin
        xyz="0 0 0"
        rpy="0 0 0" />
      <geometry>
        <mesh
          filename="package://pudong/meshes/pjjq05_2.STL" />
      </geometry>
      <material
        name="">
        <color
          rgba="1 0.49804 0 1" />
      </material>
    </visual>
    <collision>
      <origin
        xyz="0 0 0"
        rpy="0 0 0" />
      <geometry>
        <mesh
          filename="package://pudong/meshes/pjjq05_2.STL" />
      </geometry>
    </collision>
  </link>

  <!-- joint: t04_to_05_2  -->
  <joint
    name="t04_to_05_2"
    type="revolute">
    <origin
      xyz="2.4617 0.17 0.17367"
      rpy="0 0.84777 0" />
    <parent
      link="pjjq04" />
    <child
      link="pjjq05_2" />
    <axis
      xyz="0 1 0" />
    <limit
      lower="-1.7"
      upper="0.5"
      effort="0"
      velocity="1" />
    <mimic
      joint="t04_to_05_1"
      multiplier="1"
      offset="0" />
  </joint>

  <!--Made by Li Yiyang in 06.11.2021-->
  </xacro:macro>
</robot>
